Workbook

Sheet Resumo
A1: Resumo – dark patterns por IA, prompt e iteração (96 telas: ChatGPT it1/it2 e Claude it1/it2)
A2: Todos os números são fórmulas sobre a aba 'Detalhamento por tela'. Os dois modelos têm agora 2 iterações por tela e prompt (48 telas cada); a média por tela permite comparar iterações e modelos.
A4: Modelo | B4: Iteração | C4: Tipo de prompt | D4: Telas analisadas | E4: Telas com ≥1 DP | F4: % telas com DP | G4: Ocorrências | H4: Média por tela | I4: Tipos distintos
A5: ChatGPT | B5: 1 | C5: Ético | D5: =SUMPRODUCT(1*('Matriz por tela'!$A$6:$A$101="ChatGPT")*('Matriz por tela'!$B$6:$B$101=1)*('Matriz por tela'!$E$6:$E$101="Ético")) -> 8 | E5: =SUMPRODUCT(1*('Matriz por tela'!$A$6:$A$101="ChatGPT")*('Matriz por tela'!$B$6:$B$101=1)*('Matriz por tela'!$E$6:$E$101="Ético")*('Matriz por tela'!$AB$6:$AB$101>0)) -> 2 | F5: =IFERROR(E5/D5,0) -> 0.25 | G5: =SUMIFS('Detalhamento por tela'!$J$2:$J$160,'Detalhamento por tela'!$A$2:$A$160,"ChatGPT",'Detalhamento por tela'!$B$2:$B$160,1,'Detalhamento por tela'!$E$2:$E$160,"Ético") -> 2 | H5: =IFERROR(G5/D5,0) -> 0.25 | I5: =(SUMIFS('Detalhamento por tela'!$J$2:$J$160,'Detalhamento por tela'!$A$2:$A$160,"ChatGPT",'Detalhamento por tela'!$G$2:$G$160,"Dead End",'Detalhamento por tela'!$B$2:$B$160,1,'Detalhamento por tela'!$E$2:$E$160,"Ético")>0)+(SUMIFS('Detalhamento por tela'!$J$2:$J$160,'Detalhamento por tela'!$A$2:$A$160,"ChatGPT",'Detalhamento por tela'!$G$2:$G$160,"Privacy Maze",'Detalhamento por tela'!$B$2:$B$160,1,'Detalhamento por tela'!$E$2:$E$160,"Ético")>0)+(SUMIFS('Detalhamento por tela'!$J$2:$J$160,'Detalhamento por tela'!$A$2:$A$160,"ChatGPT",'Detalhamento por tela'!$G$2:$G$160,"Labyrinthine Navigation",'Detalhamento por tela'!$B$2:$B$160,1,'Detalhamento por tela'!$E$2:$E$160,"Ético")>0)+(SUMIFS('Detalhamento por tela'!$J$2:$J$160,'Detalhamento por tela'!$A$2:$A$160,"ChatGPT",'Detalhamento por tela'!$G$2:$G$160,"Reference Pricing",'Detalhamento por tela'!$B$2:$B$160,1,'Detalhamento por tela'!$E$2:$E$160,"Ético")>0)+(SUMIFS('Detalhamento por tela'!$J$2:$J$160,'Detalhamento por tela'!$A$2:$A$160,"ChatGPT",'Detalhamento por tela'!$G$2:$G$160,"Conflicting Information",'Detalhamento por tela'!$B$2:$B$160,1,'Detalhamento por tela'!$E$2:$E$160,"Ético")>0)+(SUMIFS('Detalhamento por tela'!$J$2:$J$160,'Detalhamento por tela'!$A$2:$A$160,"ChatGPT",'Detalhamento por tela'!$G$2:$G$160,"Information Without Context",'Detalhamento por tela'!$B$2:$B$160,1,'Detalhamento por tela'!$E$2:$E$160,"Ético")>0)+(SUMIFS('Detalhamento por tela'!$J$2:$J$160,'Detalhamento por tela'!$A$2:$A$160,"ChatGPT",'Detalhamento por tela'!$G$2:$G$160,"False Hierarchy",'Detalhamento por tela'!$B$2:$B$160,1,'Detalhamento por tela'!$E$2:$E$160,"Ético")>0)+(SUMIFS('Detalhamento por tela'!$J$2:$J$160,'Detalhamento por tela'!$A$2:$A$160,"ChatGPT",'Detalhamento por tela'!$G$2:$G$160,"Visual Prominence",'Detalhamento por tela'!$B$2:$B$160,1,'Detalhamento por tela'!$E$2:$E$160,"Ético")>0)+(SUMIFS('Detalhamento por tela'!$J$2:$J$160,'Detalhamento por tela'!$A$2:$A$160,"ChatGPT",'Detalhamento por tela'!$G$2:$G$160,"Bundling",'Detalhamento por tela'!$B$2:$B$160,1,'Detalhamento por tela'!$E$2:$E$160,"Ético")>0)+(SUMIFS('Detalhamento por tela'!$J$2:$J$160,'Detalhamento por tela'!$A$2:$A$160,"ChatGPT",'Detalhamento por tela'!$G$2:$G$160,"Pressured Selling",'Detalhamento por tela'!$B$2:$B$160,1,'Detalhamento por tela'!$E$2:$E$160,"Ético")>0)+(SUMIFS('Detalhamento por tela'!$J$2:$J$160,'Detalhamento por tela'!$A$2:$A$160,"ChatGPT",'Detalhamento por tela'!$G$2:$G$160,"Persuasive language",'Detalhamento por tela'!$B$2:$B$160,1,'Detalhamento por tela'!$E$2:$E$160,"Ético")>0)+(SUMIFS('Detalhamento por tela'!$J$2:$J$160,'Detalhamento por tela'!$A$2:$A$160,"ChatGPT",'Detalhamento por tela'!$G$2:$G$160,"Bad Defaults/Pre-Selection",'Detalhamento por tela'!$B$2:$B$160,1,'Detalhamento por tela'!$E$2:$E$160,"Ético")>0)+(SUMIFS('Detalhamento por tela'!$J$2:$J$160,'Detalhamento por tela'!$A$2:$A$160,"ChatGPT",'Detalhamento por tela'!$G$2:$G$160,"Positive Or Negative Framing",'Detalhamento por tela'!$B$2:$B$160,1,'Detalhamento por tela'!$E$2:$E$160,"Ético")>0)+(SUMIFS('Detalhamento por tela'!$J$2:$J$160,'Detalhamento por tela'!$A$2:$A$160,"ChatGPT",'Detalhamento por tela'!$G$2:$G$160,"Fear Of Missing Out",'Detalhamento por tela'!$B$2:$B$160,1,'Detalhamento por tela'!$E$2:$E$160,"Ético")>0)+(SUMIFS('Detalhamento por tela'!$J$2:$J$160,'Detalhamento por tela'!$A$2:$A$160,"ChatGPT",'Detalhamento por tela'!$G$2:$G$160,"Feedforward Ambiguity",'Detalhamento por tela'!$B$2:$B$160,1,'Detalhamento por tela'!$E$2:$E$160,"Ético")>0)+(SUMIFS('Detalhamento por tela'!$J$2:$J$160,'Detalhamento por tela'!$A$2:$A$160,"ChatGPT",'Detalhamento por tela'!$G$2:$G$160,"Privacy Zuckering",'Detalhamento por tela'!$B$2:$B$160,1,'Detalhamento por tela'!$E$2:$E$160,"Ético")>0)+(SUMIFS('Detalhamento por tela'!$J$2:$J$160,'Detalhamento por tela'!$A$2:$A$160,"ChatGPT",'Detalhamento por tela'!$G$2:$G$160,"High Demand",'Detalhamento por tela'!$B$2:$B$160,1,'Detalhamento por tela'!$E$2:$E$160,"Ético")>0)+(SUMIFS('Detalhamento por tela'!$J$2:$J$160,'Detalhamento por tela'!$A$2:$A$160,"ChatGPT",'Detalhamento por tela'!$G$2:$G$160,"Low Stock",'Detalhamento por tela'!$B$2:$B$160,1,'Detalhamento por tela'!$E$2:$E$160,"Ético")>0)+(SUMIFS('Detalhamento por tela'!$J$2:$J$160,'Detalhamento por tela'!$A$2:$A$160,"ChatGPT",'Detalhamento por tela'!$G$2:$G$160,"Endorsement And Testimonials",'Detalhamento por tela'!$B$2:$B$160,1,'Detalhamento por tela'!$E$2:$E$160,"Ético")>0)+(SUMIFS('Detalhamento por tela'!$J$2:$J$160,'Detalhamento por tela'!$A$2:$A$160,"ChatGPT",'Detalhamento por tela'!$G$2:$G$160,"Countdown Timer",'Detalhamento por tela'!$B$2:$B$160,1,'Detalhamento por tela'!$E$2:$E$160,"Ético")>0)+(SUMIFS('Detalhamento por tela'!$J$2:$J$160,'Detalhamento por tela'!$A$2:$A$160,"ChatGPT",'Detalhamento por tela'!$G$2:$G$160,"Limited Time Message",'Detalhamento por tela'!$B$2:$B$160,1,'Detalhamento por tela'!$E$2:$E$160,"Ético")>0) -> 2
A6: ChatGPT | B6: 1 | C6: Neutro | D6: =SUMPRODUCT(1*('Matriz por tela'!$A$6:$A$101="ChatGPT")*('Matriz por tela'!$B$6:$B$101=1)*('Matriz por tela'!$E$6:$E$101="Neutro")) -> 8 | E6: =SUMPRODUCT(1*('Matriz por tela'!$A$6:$A$101="ChatGPT")*('Matriz por tela'!$B$6:$B$101=1)*('Matriz por tela'!$E$6:$E$101="Neutro")*('Matriz por tela'!$AB$6:$AB$101>0)) -> 6 | F6: =IFERROR(E6/D6,0) -> 0.75 | G6: =SUMIFS('Detalhamento por tela'!$J$2:$J$160,'Detalhamento por tela'!$A$2:$A$160,"ChatGPT",'Detalhamento por tela'!$B$2:$B$160,1,'Detalhamento por tela'!$E$2:$E$160,"Neutro") -> 12 | H6: =IFERROR(G6/D6,0) -> 1.5 | I6: =(SUMIFS('Detalhamento por tela'!$J$2:$J$160,'Detalhamento por tela'!$A$2:$A$160,"ChatGPT",'Detalhamento por tela'!$G$2:$G$160,"Dead End",'Detalhamento por tela'!$B$2:$B$160,1,'Detalhamento por tela'!$E$2:$E$160,"Neutro")>0)+(SUMIFS('Detalhamento por tela'!$J$2:$J$160,'Detalhamento por tela'!$A$2:$A$160,"ChatGPT",'Detalhamento por tela'!$G$2:$G$160,"Privacy Maze",'Detalhamento por tela'!$B$2:$B$160,1,'Detalhamento por tela'!$E$2:$E$160,"Neutro")>0)+(SUMIFS('Detalhamento por tela'!$J$2:$J$160,'Detalhamento por tela'!$A$2:$A$160,"ChatGPT",'Detalhamento por tela'!$G$2:$G$160,"Labyrinthine Navigation",'Detalhamento por tela'!$B$2:$B$160,1,'Detalhamento por tela'!$E$2:$E$160,"Neutro")>0)+(SUMIFS('Detalhamento por tela'!$J$2:$J$160,'Detalhamento por tela'!$A$2:$A$160,"ChatGPT",'Detalhamento por tela'!$G$2:$G$160,"Reference Pricing",'Detalhamento por tela'!$B$2:$B$160,1,'Detalhamento por tela'!$E$2:$E$160,"Neutro")>0)+(SUMIFS('Detalhamento por tela'!$J$2:$J$160,'Detalhamento por tela'!$A$2:$A$160,"ChatGPT",'Detalhamento por tela'!$G$2:$G$160,"Conflicting Information",'Detalhamento por tela'!$B$2:$B$160,1,'Detalhamento por tela'!$E$2:$E$160,"Neutro")>0)+(SUMIFS('Detalhamento por tela'!$J$2:$J$160,'Detalhamento por tela'!$A$2:$A$160,"ChatGPT",'Detalhamento por tela'!$G$2:$G$160,"Information Without Context",'Detalhamento por tela'!$B$2:$B$160,1,'Detalhamento por tela'!$E$2:$E$160,"Neutro")>0)+(SUMIFS('Detalhamento por tela'!$J$2:$J$160,'Detalhamento por tela'!$A$2:$A$160,"ChatGPT",'Detalhamento por tela'!$G$2:$G$160,"False Hierarchy",'Detalhamento por tela'!$B$2:$B$160,1,'Detalhamento por tela'!$E$2:$E$160,"Neutro")>0)+(SUMIFS('Detalhamento por tela'!$J$2:$J$160,'Detalhamento por tela'!$A$2:$A$160,"ChatGPT",'Detalhamento por tela'!$G$2:$G$160,"Visual Prominence",'Detalhamento por tela'!$B$2:$B$160,1,'Detalhamento por tela'!$E$2:$E$160,"Neutro")>0)+(SUMIFS('Detalhamento por tela'!$J$2:$J$160,'Detalhamento por tela'!$A$2:$A$160,"ChatGPT",'Detalhamento por tela'!$G$2:$G$160,"Bundling",'Detalhamento por tela'!$B$2:$B$160,1,'Detalhamento por tela'!$E$2:$E$160,"Neutro")>0)+(SUMIFS('Detalhamento por tela'!$J$2:$J$160,'Detalhamento por tela'!$A$2:$A$160,"ChatGPT",'Detalhamento por tela'!$G$2:$G$160,"Pressured Selling",'Detalhamento por tela'!$B$2:$B$160,1,'Detalhamento por tela'!$E$2:$E$160,"Neutro")>0)+(SUMIFS('Detalhamento por tela'!$J$2:$J$160,'Detalhamento por tela'!$A$2:$A$160,"ChatGPT",'Detalhamento por tela'!$G$2:$G$160,"Persuasive language",'Detalhamento por tela'!$B$2:$B$160,1,'Detalhamento por tela'!$E$2:$E$160,"Neutro")>0)+(SUMIFS('Detalhamento por tela'!$J$2:$J$160,'Detalhamento por tela'!$A$2:$A$160,"ChatGPT",'Detalhamento por tela'!$G$2:$G$160,"Bad Defaults/Pre-Selection",'Detalhamento por tela'!$B$2:$B$160,1,'Detalhamento por tela'!$E$2:$E$160,"Neutro")>0)+(SUMIFS('Detalhamento por tela'!$J$2:$J$160,'Detalhamento por tela'!$A$2:$A$160,"ChatGPT",'Detalhamento por tela'!$G$2:$G$160,"Positive Or Negative Framing",'Detalhamento por tela'!$B$2:$B$160,1,'Detalhamento por tela'!$E$2:$E$160,"Neutro")>0)+(SUMIFS('Detalhamento por tela'!$J$2:$J$160,'Detalhamento por tela'!$A$2:$A$160,"ChatGPT",'Detalhamento por tela'!$G$2:$G$160,"Fear Of Missing Out",'Detalhamento por tela'!$B$2:$B$160,1,'Detalhamento por tela'!$E$2:$E$160,"Neutro")>0)+(SUMIFS('Detalhamento por tela'!$J$2:$J$160,'Detalhamento por tela'!$A$2:$A$160,"ChatGPT",'Detalhamento por tela'!$G$2:$G$160,"Feedforward Ambiguity",'Detalhamento por tela'!$B$2:$B$160,1,'Detalhamento por tela'!$E$2:$E$160,"Neutro")>0)+(SUMIFS('Detalhamento por tela'!$J$2:$J$160,'Detalhamento por tela'!$A$2:$A$160,"ChatGPT",'Detalhamento por tela'!$G$2:$G$160,"Privacy Zuckering",'Detalhamento por tela'!$B$2:$B$160,1,'Detalhamento por tela'!$E$2:$E$160,"Neutro")>0)+(SUMIFS('Detalhamento por tela'!$J$2:$J$160,'Detalhamento por tela'!$A$2:$A$160,"ChatGPT",'Detalhamento por tela'!$G$2:$G$160,"High Demand",'Detalhamento por tela'!$B$2:$B$160,1,'Detalhamento por tela'!$E$2:$E$160,"Neutro")>0)+(SUMIFS('Detalhamento por tela'!$J$2:$J$160,'Detalhamento por tela'!$A$2:$A$160,"ChatGPT",'Detalhamento por tela'!$G$2:$G$160,"Low Stock",'Detalhamento por tela'!$B$2:$B$160,1,'Detalhamento por tela'!$E$2:$E$160,"Neutro")>0)+(SUMIFS('Detalhamento por tela'!$J$2:$J$160,'Detalhamento por tela'!$A$2:$A$160,"ChatGPT",'Detalhamento por tela'!$G$2:$G$160,"Endorsement And Testimonials",'Detalhamento por tela'!$B$2:$B$160,1,'Detalhamento por tela'!$E$2:$E$160,"Neutro")>0)+(SUMIFS('Detalhamento por tela'!$J$2:$J$160,'Detalhamento por tela'!$A$2:$A$160,"ChatGPT",'Detalhamento por tela'!$G$2:$G$160,"Countdown Timer",'Detalhamento por tela'!$B$2:$B$160,1,'Detalhamento por tela'!$E$2:$E$160,"Neutro")>0)+(SUMIFS('Detalhamento por tela'!$J$2:$J$160,'Detalhamento por tela'!$A$2:$A$160,"ChatGPT",'Detalhamento por tela'!$G$2:$G$160,"Limited Time Message",'Detalhamento por tela'!$B$2:$B$160,1,'Detalhamento por tela'!$E$2:$E$160,"Neutro")>0) -> 7
A7: ChatGPT | B7: 1 | C7: Tendencioso | D7: =SUMPRODUCT(1*('Matriz por tela'!$A$6:$A$101="ChatGPT")*('Matriz por tela'!$B$6:$B$101=1)*('Matriz por tela'!$E$6:$E$101="Tendencioso")) -> 8 | E7: =SUMPRODUCT(1*('Matriz por tela'!$A$6:$A$101="ChatGPT")*('Matriz por tela'!$B$6:$B$101=1)*('Matriz por tela'!$E$6:$E$101="Tendencioso")*('Matriz por tela'!$AB$6:$AB$101>0)) -> 7 | F7: =IFERROR(E7/D7,0) -> 0.875 | G7: =SUMIFS('Detalhamento por tela'!$J$2:$J$160,'Detalhamento por tela'!$A$2:$A$160,"ChatGPT",'Detalhamento por tela'!$B$2:$B$160,1,'Detalhamento por tela'!$E$2:$E$160,"Tendencioso") -> 16 | H7: =IFERROR(G7/D7,0) -> 2 | I7: =(SUMIFS('Detalhamento por tela'!$J$2:$J$160,'Detalhamento por tela'!$A$2:$A$160,"ChatGPT",'Detalhamento por tela'!$G$2:$G$160,"Dead End",'Detalhamento por tela'!$B$2:$B$160,1,'Detalhamento por tela'!$E$2:$E$160,"Tendencioso")>0)+(SUMIFS('Detalhamento por tela'!$J$2:$J$160,'Detalhamento por tela'!$A$2:$A$160,"ChatGPT",'Detalhamento por tela'!$G$2:$G$160,"Privacy Maze",'Detalhamento por tela'!$B$2:$B$160,1,'Detalhamento por tela'!$E$2:$E$160,"Tendencioso")>0)+(SUMIFS('Detalhamento por tela'!$J$2:$J$160,'Detalhamento por tela'!$A$2:$A$160,"ChatGPT",'Detalhamento por tela'!$G$2:$G$160,"Labyrinthine Navigation",'Detalhamento por tela'!$B$2:$B$160,1,'Detalhamento por tela'!$E$2:$E$160,"Tendencioso")>0)+(SUMIFS('Detalhamento por tela'!$J$2:$J$160,'Detalhamento por tela'!$A$2:$A$160,"ChatGPT",'Detalhamento por tela'!$G$2:$G$160,"Reference Pricing",'Detalhamento por tela'!$B$2:$B$160,1,'Detalhamento por tela'!$E$2:$E$160,"Tendencioso")>0)+(SUMIFS('Detalhamento por tela'!$J$2:$J$160,'Detalhamento por tela'!$A$2:$A$160,"ChatGPT",'Detalhamento por tela'!$G$2:$G$160,"Conflicting Information",'Detalhamento por tela'!$B$2:$B$160,1,'Detalhamento por tela'!$E$2:$E$160,"Tendencioso")>0)+(SUMIFS('Detalhamento por tela'!$J$2:$J$160,'Detalhamento por tela'!$A$2:$A$160,"ChatGPT",'Detalhamento por tela'!$G$2:$G$160,"Information Without Context",'Detalhamento por tela'!$B$2:$B$160,1,'Detalhamento por tela'!$E$2:$E$160,"Tendencioso")>0)+(SUMIFS('Detalhamento por tela'!$J$2:$J$160,'Detalhamento por tela'!$A$2:$A$160,"ChatGPT",'Detalhamento por tela'!$G$2:$G$160,"False Hierarchy",'Detalhamento por tela'!$B$2:$B$160,1,'Detalhamento por tela'!$E$2:$E$160,"Tendencioso")>0)+(SUMIFS('Detalhamento por tela'!$J$2:$J$160,'Detalhamento por tela'!$A$2:$A$160,"ChatGPT",'Detalhamento por tela'!$G$2:$G$160,"Visual Prominence",'Detalhamento por tela'!$B$2:$B$160,1,'Detalhamento por tela'!$E$2:$E$160,"Tendencioso")>0)+(SUMIFS('Detalhamento por tela'!$J$2:$J$160,'Detalhamento por tela'!$A$2:$A$160,"ChatGPT",'Detalhamento por tela'!$G$2:$G$160,"Bundling",'Detalhamento por tela'!$B$2:$B$160,1,'Detalhamento por tela'!$E$2:$E$160,"Tendencioso")>0)+(SUMIFS('Detalhamento por tela'!$J$2:$J$160,'Detalhamento por tela'!$A$2:$A$160,"ChatGPT",'Detalhamento por tela'!$G$2:$G$160,"Pressured Selling",'Detalhamento por tela'!$B$2:$B$160,1,'Detalhamento por tela'!$E$2:$E$160,"Tendencioso")>0)+(SUMIFS('Detalhamento por tela'!$J$2:$J$160,'Detalhamento por tela'!$A$2:$A$160,"ChatGPT",'Detalhamento por tela'!$G$2:$G$160,"Persuasive language",'Detalhamento por tela'!$B$2:$B$160,1,'Detalhamento por tela'!$E$2:$E$160,"Tendencioso")>0)+(SUMIFS('Detalhamento por tela'!$J$2:$J$160,'Detalhamento por tela'!$A$2:$A$160,"ChatGPT",'Detalhamento por tela'!$G$2:$G$160,"Bad Defaults/Pre-Selection",'Detalhamento por tela'!$B$2:$B$160,1,'Detalhamento por tela'!$E$2:$E$160,"Tendencioso")>0)+(SUMIFS('Detalhamento por tela'!$J$2:$J$160,'Detalhamento por tela'!$A$2:$A$160,"ChatGPT",'Detalhamento por tela'!$G$2:$G$160,"Positive Or Negative Framing",'Detalhamento por tela'!$B$2:$B$160,1,'Detalhamento por tela'!$E$2:$E$160,"Tendencioso")>0)+(SUMIFS('Detalhamento por tela'!$J$2:$J$160,'Detalhamento por tela'!$A$2:$A$160,"ChatGPT",'Detalhamento por tela'!$G$2:$G$160,"Fear Of Missing Out",'Detalhamento por tela'!$B$2:$B$160,1,'Detalhamento por tela'!$E$2:$E$160,"Tendencioso")>0)+(SUMIFS('Detalhamento por tela'!$J$2:$J$160,'Detalhamento por tela'!$A$2:$A$160,"ChatGPT",'Detalhamento por tela'!$G$2:$G$160,"Feedforward Ambiguity",'Detalhamento por tela'!$B$2:$B$160,1,'Detalhamento por tela'!$E$2:$E$160,"Tendencioso")>0)+(SUMIFS('Detalhamento por tela'!$J$2:$J$160,'Detalhamento por tela'!$A$2:$A$160,"ChatGPT",'Detalhamento por tela'!$G$2:$G$160,"Privacy Zuckering",'Detalhamento por tela'!$B$2:$B$160,1,'Detalhamento por tela'!$E$2:$E$160,"Tendencioso")>0)+(SUMIFS('Detalhamento por tela'!$J$2:$J$160,'Detalhamento por tela'!$A$2:$A$160,"ChatGPT",'Detalhamento por tela'!$G$2:$G$160,"High Demand",'Detalhamento por tela'!$B$2:$B$160,1,'Detalhamento por tela'!$E$2:$E$160,"Tendencioso")>0)+(SUMIFS('Detalhamento por tela'!$J$2:$J$160,'Detalhamento por tela'!$A$2:$A$160,"ChatGPT",'Detalhamento por tela'!$G$2:$G$160,"Low Stock",'Detalhamento por tela'!$B$2:$B$160,1,'Detalhamento por tela'!$E$2:$E$160,"Tendencioso")>0)+(SUMIFS('Detalhamento por tela'!$J$2:$J$160,'Detalhamento por tela'!$A$2:$A$160,"ChatGPT",'Detalhamento por tela'!$G$2:$G$160,"Endorsement And Testimonials",'Detalhamento por tela'!$B$2:$B$160,1,'Detalhamento por tela'!$E$2:$E$160,"Tendencioso")>0)+(SUMIFS('Detalhamento por tela'!$J$2:$J$160,'Detalhamento por tela'!$A$2:$A$160,"ChatGPT",'Detalhamento por tela'!$G$2:$G$160,"Countdown Timer",'Detalhamento por tela'!$B$2:$B$160,1,'Detalhamento por tela'!$E$2:$E$160,"Tendencioso")>0)+(SUMIFS('Detalhamento por tela'!$J$2:$J$160,'Detalhamento por tela'!$A$2:$A$160,"ChatGPT",'Detalhamento por tela'!$G$2:$G$160,"Limited Time Message",'Detalhamento por tela'!$B$2:$B$160,1,'Detalhamento por tela'!$E$2:$E$160,"Tendencioso")>0) -> 10
A8: ChatGPT | B8: 1 | C8: Total | D8: =SUMPRODUCT(1*('Matriz por tela'!$A$6:$A$101="ChatGPT")*('Matriz por tela'!$B$6:$B$101=1)) -> 24 | E8: =SUMPRODUCT(1*('Matriz por tela'!$A$6:$A$101="ChatGPT")*('Matriz por tela'!$B$6:$B$101=1)*('Matriz por tela'!$AB$6:$AB$101>0)) -> 15 | F8: =IFERROR(E8/D8,0) -> 0.625 | G8: =SUMIFS('Detalhamento por tela'!$J$2:$J$160,'Detalhamento por tela'!$A$2:$A$160,"ChatGPT",'Detalhamento por tela'!$B$2:$B$160,1) -> 30 | H8: =IFERROR(G8/D8,0) -> 1.25 | I8: =(SUMIFS('Detalhamento por tela'!$J$2:$J$160,'Detalhamento por tela'!$A$2:$A$160,"ChatGPT",'Detalhamento por tela'!$G$2:$G$160,"Dead End",'Detalhamento por tela'!$B$2:$B$160,1)>0)+(SUMIFS('Detalhamento por tela'!$J$2:$J$160,'Detalhamento por tela'!$A$2:$A$160,"ChatGPT",'Detalhamento por tela'!$G$2:$G$160,"Privacy Maze",'Detalhamento por tela'!$B$2:$B$160,1)>0)+(SUMIFS('Detalhamento por tela'!$J$2:$J$160,'Detalhamento por tela'!$A$2:$A$160,"ChatGPT",'Detalhamento por tela'!$G$2:$G$160,"Labyrinthine Navigation",'Detalhamento por tela'!$B$2:$B$160,1)>0)+(SUMIFS('Detalhamento por tela'!$J$2:$J$160,'Detalhamento por tela'!$A$2:$A$160,"ChatGPT",'Detalhamento por tela'!$G$2:$G$160,"Reference Pricing",'Detalhamento por tela'!$B$2:$B$160,1)>0)+(SUMIFS('Detalhamento por tela'!$J$2:$J$160,'Detalhamento por tela'!$A$2:$A$160,"ChatGPT",'Detalhamento por tela'!$G$2:$G$160,"Conflicting Information",'Detalhamento por tela'!$B$2:$B$160,1)>0)+(SUMIFS('Detalhamento por tela'!$J$2:$J$160,'Detalhamento por tela'!$A$2:$A$160,"ChatGPT",'Detalhamento por tela'!$G$2:$G$160,"Information Without Context",'Detalhamento por tela'!$B$2:$B$160,1)>0)+(SUMIFS('Detalhamento por tela'!$J$2:$J$160,'Detalhamento por tela'!$A$2:$A$160,"ChatGPT",'Detalhamento por tela'!$G$2:$G$160,"False Hierarchy",'Detalhamento por tela'!$B$2:$B$160,1)>0)+(SUMIFS('Detalhamento por tela'!$J$2:$J$160,'Detalhamento por tela'!$A$2:$A$160,"ChatGPT",'Detalhamento por tela'!$G$2:$G$160,"Visual Prominence",'Detalhamento por tela'!$B$2:$B$160,1)>0)+(SUMIFS('Detalhamento por tela'!$J$2:$J$160,'Detalhamento por tela'!$A$2:$A$160,"ChatGPT",'Detalhamento por tela'!$G$2:$G$160,"Bundling",'Detalhamento por tela'!$B$2:$B$160,1)>0)+(SUMIFS('Detalhamento por tela'!$J$2:$J$160,'Detalhamento por tela'!$A$2:$A$160,"ChatGPT",'Detalhamento por tela'!$G$2:$G$160,"Pressured Selling",'Detalhamento por tela'!$B$2:$B$160,1)>0)+(SUMIFS('Detalhamento por tela'!$J$2:$J$160,'Detalhamento por tela'!$A$2:$A$160,"ChatGPT",'Detalhamento por tela'!$G$2:$G$160,"Persuasive language",'Detalhamento por tela'!$B$2:$B$160,1)>0)+(SUMIFS('Detalhamento por tela'!$J$2:$J$160,'Detalhamento por tela'!$A$2:$A$160,"ChatGPT",'Detalhamento por tela'!$G$2:$G$160,"Bad Defaults/Pre-Selection",'Detalhamento por tela'!$B$2:$B$160,1)>0)+(SUMIFS('Detalhamento por tela'!$J$2:$J$160,'Detalhamento por tela'!$A$2:$A$160,"ChatGPT",'Detalhamento por tela'!$G$2:$G$160,"Positive Or Negative Framing",'Detalhamento por tela'!$B$2:$B$160,1)>0)+(SUMIFS('Detalhamento por tela'!$J$2:$J$160,'Detalhamento por tela'!$A$2:$A$160,"ChatGPT",'Detalhamento por tela'!$G$2:$G$160,"Fear Of Missing Out",'Detalhamento por tela'!$B$2:$B$160,1)>0)+(SUMIFS('Detalhamento por tela'!$J$2:$J$160,'Detalhamento por tela'!$A$2:$A$160,"ChatGPT",'Detalhamento por tela'!$G$2:$G$160,"Feedforward Ambiguity",'Detalhamento por tela'!$B$2:$B$160,1)>0)+(SUMIFS('Detalhamento por tela'!$J$2:$J$160,'Detalhamento por tela'!$A$2:$A$160,"ChatGPT",'Detalhamento por tela'!$G$2:$G$160,"Privacy Zuckering",'Detalhamento por tela'!$B$2:$B$160,1)>0)+(SUMIFS('Detalhamento por tela'!$J$2:$J$160,'Detalhamento por tela'!$A$2:$A$160,"ChatGPT",'Detalhamento por tela'!$G$2:$G$160,"High Demand",'Detalhamento por tela'!$B$2:$B$160,1)>0)+(SUMIFS('Detalhamento por tela'!$J$2:$J$160,'Detalhamento por tela'!$A$2:$A$160,"ChatGPT",'Detalhamento por tela'!$G$2:$G$160,"Low Stock",'Detalhamento por tela'!$B$2:$B$160,1)>0)+(SUMIFS('Detalhamento por tela'!$J$2:$J$160,'Detalhamento por tela'!$A$2:$A$160,"ChatGPT",'Detalhamento por tela'!$G$2:$G$160,"Endorsement And Testimonials",'Detalhamento por tela'!$B$2:$B$160,1)>0)+(SUMIFS('Detalhamento por tela'!$J$2:$J$160,'Detalhamento por tela'!$A$2:$A$160,"ChatGPT",'Detalhamento por tela'!$G$2:$G$160,"Countdown Timer",'Detalhamento por tela'!$B$2:$B$160,1)>0)+(SUMIFS('Detalhamento por tela'!$J$2:$J$160,'Detalhamento por tela'!$A$2:$A$160,"ChatGPT",'Detalhamento por tela'!$G$2:$G$160,"Limited Time Message",'Detalhamento por tela'!$B$2:$B$160,1)>0) -> 11
A9: ChatGPT | B9: 2 | C9: Ético | D9: =SUMPRODUCT(1*('Matriz por tela'!$A$6:$A$101="ChatGPT")*('Matriz por tela'!$B$6:$B$101=2)*('Matriz por tela'!$E$6:$E$101="Ético")) -> 8 | E9: =SUMPRODUCT(1*('Matriz por tela'!$A$6:$A$101="ChatGPT")*('Matriz por tela'!$B$6:$B$101=2)*('Matriz por tela'!$E$6:$E$101="Ético")*('Matriz por tela'!$AB$6:$AB$101>0)) -> 5 | F9: =IFERROR(E9/D9,0) -> 0.625 | G9: =SUMIFS('Detalhamento por tela'!$J$2:$J$160,'Detalhamento por tela'!$A$2:$A$160,"ChatGPT",'Detalhamento por tela'!$B$2:$B$160,2,'Detalhamento por tela'!$E$2:$E$160,"Ético") -> 5 | H9: =IFERROR(G9/D9,0) -> 0.625 | I9: =(SUMIFS('Detalhamento por tela'!$J$2:$J$160,'Detalhamento por tela'!$A$2:$A$160,"ChatGPT",'Detalhamento por tela'!$G$2:$G$160,"Dead End",'Detalhamento por tela'!$B$2:$B$160,2,'Detalhamento por tela'!$E$2:$E$160,"Ético")>0)+(SUMIFS('Detalhamento por tela'!$J$2:$J$160,'Detalhamento por tela'!$A$2:$A$160,"ChatGPT",'Detalhamento por tela'!$G$2:$G$160,"Privacy Maze",'Detalhamento por tela'!$B$2:$B$160,2,'Detalhamento por tela'!$E$2:$E$160,"Ético")>0)+(SUMIFS('Detalhamento por tela'!$J$2:$J$160,'Detalhamento por tela'!$A$2:$A$160,"ChatGPT",'Detalhamento por tela'!$G$2:$G$160,"Labyrinthine Navigation",'Detalhamento por tela'!$B$2:$B$160,2,'Detalhamento por tela'!$E$2:$E$160,"Ético")>0)+(SUMIFS('Detalhamento por tela'!$J$2:$J$160,'Detalhamento por tela'!$A$2:$A$160,"ChatGPT",'Detalhamento por tela'!$G$2:$G$160,"Reference Pricing",'Detalhamento por tela'!$B$2:$B$160,2,'Detalhamento por tela'!$E$2:$E$160,"Ético")>0)+(SUMIFS('Detalhamento por tela'!$J$2:$J$160,'Detalhamento por tela'!$A$2:$A$160,"ChatGPT",'Detalhamento por tela'!$G$2:$G$160,"Conflicting Information",'Detalhamento por tela'!$B$2:$B$160,2,'Detalhamento por tela'!$E$2:$E$160,"Ético")>0)+(SUMIFS('Detalhamento por tela'!$J$2:$J$160,'Detalhamento por tela'!$A$2:$A$160,"ChatGPT",'Detalhamento por tela'!$G$2:$G$160,"Information Without Context",'Detalhamento por tela'!$B$2:$B$160,2,'Detalhamento por tela'!$E$2:$E$160,"Ético")>0)+(SUMIFS('Detalhamento por tela'!$J$2:$J$160,'Detalhamento por tela'!$A$2:$A$160,"ChatGPT",'Detalhamento por tela'!$G$2:$G$160,"False Hierarchy",'Detalhamento por tela'!$B$2:$B$160,2,'Detalhamento por tela'!$E$2:$E$160,"Ético")>0)+(SUMIFS('Detalhamento por tela'!$J$2:$J$160,'Detalhamento por tela'!$A$2:$A$160,"ChatGPT",'Detalhamento por tela'!$G$2:$G$160,"Visual Prominence",'Detalhamento por tela'!$B$2:$B$160,2,'Detalhamento por tela'!$E$2:$E$160,"Ético")>0)+(SUMIFS('Detalhamento por tela'!$J$2:$J$160,'Detalhamento por tela'!$A$2:$A$160,"ChatGPT",'Detalhamento por tela'!$G$2:$G$160,"Bundling",'Detalhamento por tela'!$B$2:$B$160,2,'Detalhamento por tela'!$E$2:$E$160,"Ético")>0)+(SUMIFS('Detalhamento por tela'!$J$2:$J$160,'Detalhamento por tela'!$A$2:$A$160,"ChatGPT",'Detalhamento por tela'!$G$2:$G$160,"Pressured Selling",'Detalhamento por tela'!$B$2:$B$160,2,'Detalhamento por tela'!$E$2:$E$160,"Ético")>0)+(SUMIFS('Detalhamento por tela'!$J$2:$J$160,'Detalhamento por tela'!$A$2:$A$160,"ChatGPT",'Detalhamento por tela'!$G$2:$G$160,"Persuasive language",'Detalhamento por tela'!$B$2:$B$160,2,'Detalhamento por tela'!$E$2:$E$160,"Ético")>0)+(SUMIFS('Detalhamento por tela'!$J$2:$J$160,'Detalhamento por tela'!$A$2:$A$160,"ChatGPT",'Detalhamento por tela'!$G$2:$G$160,"Bad Defaults/Pre-Selection",'Detalhamento por tela'!$B$2:$B$160,2,'Detalhamento por tela'!$E$2:$E$160,"Ético")>0)+(SUMIFS('Detalhamento por tela'!$J$2:$J$160,'Detalhamento por tela'!$A$2:$A$160,"ChatGPT",'Detalhamento por tela'!$G$2:$G$160,"Positive Or Negative Framing",'Detalhamento por tela'!$B$2:$B$160,2,'Detalhamento por tela'!$E$2:$E$160,"Ético")>0)+(SUMIFS('Detalhamento por tela'!$J$2:$J$160,'Detalhamento por tela'!$A$2:$A$160,"ChatGPT",'Detalhamento por tela'!$G$2:$G$160,"Fear Of Missing Out",'Detalhamento por tela'!$B$2:$B$160,2,'Detalhamento por tela'!$E$2:$E$160,"Ético")>0)+(SUMIFS('Detalhamento por tela'!$J$2:$J$160,'Detalhamento por tela'!$A$2:$A$160,"ChatGPT",'Detalhamento por tela'!$G$2:$G$160,"Feedforward Ambiguity",'Detalhamento por tela'!$B$2:$B$160,2,'Detalhamento por tela'!$E$2:$E$160,"Ético")>0)+(SUMIFS('Detalhamento por tela'!$J$2:$J$160,'Detalhamento por tela'!$A$2:$A$160,"ChatGPT",'Detalhamento por tela'!$G$2:$G$160,"Privacy Zuckering",'Detalhamento por tela'!$B$2:$B$160,2,'Detalhamento por tela'!$E$2:$E$160,"Ético")>0)+(SUMIFS('Detalhamento por tela'!$J$2:$J$160,'Detalhamento por tela'!$A$2:$A$160,"ChatGPT",'Detalhamento por tela'!$G$2:$G$160,"High Demand",'Detalhamento por tela'!$B$2:$B$160,2,'Detalhamento por tela'!$E$2:$E$160,"Ético")>0)+(SUMIFS('Detalhamento por tela'!$J$2:$J$160,'Detalhamento por tela'!$A$2:$A$160,"ChatGPT",'Detalhamento por tela'!$G$2:$G$160,"Low Stock",'Detalhamento por tela'!$B$2:$B$160,2,'Detalhamento por tela'!$E$2:$E$160,"Ético")>0)+(SUMIFS('Detalhamento por tela'!$J$2:$J$160,'Detalhamento por tela'!$A$2:$A$160,"ChatGPT",'Detalhamento por tela'!$G$2:$G$160,"Endorsement And Testimonials",'Detalhamento por tela'!$B$2:$B$160,2,'Detalhamento por tela'!$E$2:$E$160,"Ético")>0)+(SUMIFS('Detalhamento por tela'!$J$2:$J$160,'Detalhamento por tela'!$A$2:$A$160,"ChatGPT",'Detalhamento por tela'!$G$2:$G$160,"Countdown Timer",'Detalhamento por tela'!$B$2:$B$160,2,'Detalhamento por tela'!$E$2:$E$160,"Ético")>0)+(SUMIFS('Detalhamento por tela'!$J$2:$J$160,'Detalhamento por tela'!$A$2:$A$160,"ChatGPT",'Detalhamento por tela'!$G$2:$G$160,"Limited Time Message",'Detalhamento por tela'!$B$2:$B$160,2,'Detalhamento por tela'!$E$2:$E$160,"Ético")>0) -> 4
A10: ChatGPT | B10: 2 | C10: Neutro | D10: =SUMPRODUCT(1*('Matriz por tela'!$A$6:$A$101="ChatGPT")*('Matriz por tela'!$B$6:$B$101=2)*('Matriz por tela'!$E$6:$E$101="Neutro")) -> 8 | E10: =SUMPRODUCT(1*('Matriz por tela'!$A$6:$A$101="ChatGPT")*('Matriz por tela'!$B$6:$B$101=2)*('Matriz por tela'!$E$6:$E$101="Neutro")*('Matriz por tela'!$AB$6:$AB$101>0)) -> 6 | F10: =IFERROR(E10/D10,0) -> 0.75 | G10: =SUMIFS('Detalhamento por tela'!$J$2:$J$160,'Detalhamento por tela'!$A$2:$A$160,"ChatGPT",'Detalhamento por tela'!$B$2:$B$160,2,'Detalhamento por tela'!$E$2:$E$160,"Neutro") -> 12 | H10: =IFERROR(G10/D10,0) -> 1.5 | I10: =(SUMIFS('Detalhamento por tela'!$J$2:$J$160,'Detalhamento por tela'!$A$2:$A$160,"ChatGPT",'Detalhamento por tela'!$G$2:$G$160,"Dead End",'Detalhamento por tela'!$B$2:$B$160,2,'Detalhamento por tela'!$E$2:$E$160,"Neutro")>0)+(SUMIFS('Detalhamento por tela'!$J$2:$J$160,'Detalhamento por tela'!$A$2:$A$160,"ChatGPT",'Detalhamento por tela'!$G$2:$G$160,"Privacy Maze",'Detalhamento por tela'!$B$2:$B$160,2,'Detalhamento por tela'!$E$2:$E$160,"Neutro")>0)+(SUMIFS('Detalhamento por tela'!$J$2:$J$160,'Detalhamento por tela'!$A$2:$A$160,"ChatGPT",'Detalhamento por tela'!$G$2:$G$160,"Labyrinthine Navigation",'Detalhamento por tela'!$B$2:$B$160,2,'Detalhamento por tela'!$E$2:$E$160,"Neutro")>0)+(SUMIFS('Detalhamento por tela'!$J$2:$J$160,'Detalhamento por tela'!$A$2:$A$160,"ChatGPT",'Detalhamento por tela'!$G$2:$G$160,"Reference Pricing",'Detalhamento por tela'!$B$2:$B$160,2,'Detalhamento por tela'!$E$2:$E$160,"Neutro")>0)+(SUMIFS('Detalhamento por tela'!$J$2:$J$160,'Detalhamento por tela'!$A$2:$A$160,"ChatGPT",'Detalhamento por tela'!$G$2:$G$160,"Conflicting Information",'Detalhamento por tela'!$B$2:$B$160,2,'Detalhamento por tela'!$E$2:$E$160,"Neutro")>0)+(SUMIFS('Detalhamento por tela'!$J$2:$J$160,'Detalhamento por tela'!$A$2:$A$160,"ChatGPT",'Detalhamento por tela'!$G$2:$G$160,"Information Without Context",'Detalhamento por tela'!$B$2:$B$160,2,'Detalhamento por tela'!$E$2:$E$160,"Neutro")>0)+(SUMIFS('Detalhamento por tela'!$J$2:$J$160,'Detalhamento por tela'!$A$2:$A$160,"ChatGPT",'Detalhamento por tela'!$G$2:$G$160,"False Hierarchy",'Detalhamento por tela'!$B$2:$B$160,2,'Detalhamento por tela'!$E$2:$E$160,"Neutro")>0)+(SUMIFS('Detalhamento por tela'!$J$2:$J$160,'Detalhamento por tela'!$A$2:$A$160,"ChatGPT",'Detalhamento por tela'!$G$2:$G$160,"Visual Prominence",'Detalhamento por tela'!$B$2:$B$160,2,'Detalhamento por tela'!$E$2:$E$160,"Neutro")>0)+(SUMIFS('Detalhamento por tela'!$J$2:$J$160,'Detalhamento por tela'!$A$2:$A$160,"ChatGPT",'Detalhamento por tela'!$G$2:$G$160,"Bundling",'Detalhamento por tela'!$B$2:$B$160,2,'Detalhamento por tela'!$E$2:$E$160,"Neutro")>0)+(SUMIFS('Detalhamento por tela'!$J$2:$J$160,'Detalhamento por tela'!$A$2:$A$160,"ChatGPT",'Detalhamento por tela'!$G$2:$G$160,"Pressured Selling",'Detalhamento por tela'!$B$2:$B$160,2,'Detalhamento por tela'!$E$2:$E$160,"Neutro")>0)+(SUMIFS('Detalhamento por tela'!$J$2:$J$160,'Detalhamento por tela'!$A$2:$A$160,"ChatGPT",'Detalhamento por tela'!$G$2:$G$160,"Persuasive language",'Detalhamento por tela'!$B$2:$B$160,2,'Detalhamento por tela'!$E$2:$E$160,"Neutro")>0)+(SUMIFS('Detalhamento por tela'!$J$2:$J$160,'Detalhamento por tela'!$A$2:$A$160,"ChatGPT",'Detalhamento por tela'!$G$2:$G$160,"Bad Defaults/Pre-Selection",'Detalhamento por tela'!$B$2:$B$160,2,'Detalhamento por tela'!$E$2:$E$160,"Neutro")>0)+(SUMIFS('Detalhamento por tela'!$J$2:$J$160,'Detalhamento por tela'!$A$2:$A$160,"ChatGPT",'Detalhamento por tela'!$G$2:$G$160,"Positive Or Negative Framing",'Detalhamento por tela'!$B$2:$B$160,2,'Detalhamento por tela'!$E$2:$E$160,"Neutro")>0)+(SUMIFS('Detalhamento por tela'!$J$2:$J$160,'Detalhamento por tela'!$A$2:$A$160,"ChatGPT",'Detalhamento por tela'!$G$2:$G$160,"Fear Of Missing Out",'Detalhamento por tela'!$B$2:$B$160,2,'Detalhamento por tela'!$E$2:$E$160,"Neutro")>0)+(SUMIFS('Detalhamento por tela'!$J$2:$J$160,'Detalhamento por tela'!$A$2:$A$160,"ChatGPT",'Detalhamento por tela'!$G$2:$G$160,"Feedforward Ambiguity",'Detalhamento por tela'!$B$2:$B$160,2,'Detalhamento por tela'!$E$2:$E$160,"Neutro")>0)+(SUMIFS('Detalhamento por tela'!$J$2:$J$160,'Detalhamento por tela'!$A$2:$A$160,"ChatGPT",'Detalhamento por tela'!$G$2:$G$160,"Privacy Zuckering",'Detalhamento por tela'!$B$2:$B$160,2,'Detalhamento por tela'!$E$2:$E$160,"Neutro")>0)+(SUMIFS('Detalhamento por tela'!$J$2:$J$160,'Detalhamento por tela'!$A$2:$A$160,"ChatGPT",'Detalhamento por tela'!$G$2:$G$160,"High Demand",'Detalhamento por tela'!$B$2:$B$160,2,'Detalhamento por tela'!$E$2:$E$160,"Neutro")>0)+(SUMIFS('Detalhamento por tela'!$J$2:$J$160,'Detalhamento por tela'!$A$2:$A$160,"ChatGPT",'Detalhamento por tela'!$G$2:$G$160,"Low Stock",'Detalhamento por tela'!$B$2:$B$160,2,'Detalhamento por tela'!$E$2:$E$160,"Neutro")>0)+(SUMIFS('Detalhamento por tela'!$J$2:$J$160,'Detalhamento por tela'!$A$2:$A$160,"ChatGPT",'Detalhamento por tela'!$G$2:$G$160,"Endorsement And Testimonials",'Detalhamento por tela'!$B$2:$B$160,2,'Detalhamento por tela'!$E$2:$E$160,"Neutro")>0)+(SUMIFS('Detalhamento por tela'!$J$2:$J$160,'Detalhamento por tela'!$A$2:$A$160,"ChatGPT",'Detalhamento por tela'!$G$2:$G$160,"Countdown Timer",'Detalhamento por tela'!$B$2:$B$160,2,'Detalhamento por tela'!$E$2:$E$160,"Neutro")>0)+(SUMIFS('Detalhamento por tela'!$J$2:$J$160,'Detalhamento por tela'!$A$2:$A$160,"ChatGPT",'Detalhamento por tela'!$G$2:$G$160,"Limited Time Message",'Detalhamento por tela'!$B$2:$B$160,2,'Detalhamento por tela'!$E$2:$E$160,"Neutro")>0) -> 7
A11: ChatGPT | B11: 2 | C11: Tendencioso | D11: =SUMPRODUCT(1*('Matriz por tela'!$A$6:$A$101="ChatGPT")*('Matriz por tela'!$B$6:$B$101=2)*('Matriz por tela'!$E$6:$E$101="Tendencioso")) -> 8 | E11: =SUMPRODUCT(1*('Matriz por tela'!$A$6:$A$101="ChatGPT")*('Matriz por tela'!$B$6:$B$101=2)*('Matriz por tela'!$E$6:$E$101="Tendencioso")*('Matriz por tela'!$AB$6:$AB$101>0)) -> 6 | F11: =IFERROR(E11/D11,0) -> 0.75 | G11: =SUMIFS('Detalhamento por tela'!$J$2:$J$160,'Detalhamento por tela'!$A$2:$A$160,"ChatGPT",'Detalhamento por tela'!$B$2:$B$160,2,'Detalhamento por tela'!$E$2:$E$160,"Tendencioso") -> 16 | H11: =IFERROR(G11/D11,0) -> 2 | I11: =(SUMIFS('Detalhamento por tela'!$J$2:$J$160,'Detalhamento por tela'!$A$2:$A$160,"ChatGPT",'Detalhamento por tela'!$G$2:$G$160,"Dead End",'Detalhamento por tela'!$B$2:$B$160,2,'Detalhamento por tela'!$E$2:$E$160,"Tendencioso")>0)+(SUMIFS('Detalhamento por tela'!$J$2:$J$160,'Detalhamento por tela'!$A$2:$A$160,"ChatGPT",'Detalhamento por tela'!$G$2:$G$160,"Privacy Maze",'Detalhamento por tela'!$B$2:$B$160,2,'Detalhamento por tela'!$E$2:$E$160,"Tendencioso")>0)+(SUMIFS('Detalhamento por tela'!$J$2:$J$160,'Detalhamento por tela'!$A$2:$A$160,"ChatGPT",'Detalhamento por tela'!$G$2:$G$160,"Labyrinthine Navigation",'Detalhamento por tela'!$B$2:$B$160,2,'Detalhamento por tela'!$E$2:$E$160,"Tendencioso")>0)+(SUMIFS('Detalhamento por tela'!$J$2:$J$160,'Detalhamento por tela'!$A$2:$A$160,"ChatGPT",'Detalhamento por tela'!$G$2:$G$160,"Reference Pricing",'Detalhamento por tela'!$B$2:$B$160,2,'Detalhamento por tela'!$E$2:$E$160,"Tendencioso")>0)+(SUMIFS('Detalhamento por tela'!$J$2:$J$160,'Detalhamento por tela'!$A$2:$A$160,"ChatGPT",'Detalhamento por tela'!$G$2:$G$160,"Conflicting Information",'Detalhamento por tela'!$B$2:$B$160,2,'Detalhamento por tela'!$E$2:$E$160,"Tendencioso")>0)+(SUMIFS('Detalhamento por tela'!$J$2:$J$160,'Detalhamento por tela'!$A$2:$A$160,"ChatGPT",'Detalhamento por tela'!$G$2:$G$160,"Information Without Context",'Detalhamento por tela'!$B$2:$B$160,2,'Detalhamento por tela'!$E$2:$E$160,"Tendencioso")>0)+(SUMIFS('Detalhamento por tela'!$J$2:$J$160,'Detalhamento por tela'!$A$2:$A$160,"ChatGPT",'Detalhamento por tela'!$G$2:$G$160,"False Hierarchy",'Detalhamento por tela'!$B$2:$B$160,2,'Detalhamento por tela'!$E$2:$E$160,"Tendencioso")>0)+(SUMIFS('Detalhamento por tela'!$J$2:$J$160,'Detalhamento por tela'!$A$2:$A$160,"ChatGPT",'Detalhamento por tela'!$G$2:$G$160,"Visual Prominence",'Detalhamento por tela'!$B$2:$B$160,2,'Detalhamento por tela'!$E$2:$E$160,"Tendencioso")>0)+(SUMIFS('Detalhamento por tela'!$J$2:$J$160,'Detalhamento por tela'!$A$2:$A$160,"ChatGPT",'Detalhamento por tela'!$G$2:$G$160,"Bundling",'Detalhamento por tela'!$B$2:$B$160,2,'Detalhamento por tela'!$E$2:$E$160,"Tendencioso")>0)+(SUMIFS('Detalhamento por tela'!$J$2:$J$160,'Detalhamento por tela'!$A$2:$A$160,"ChatGPT",'Detalhamento por tela'!$G$2:$G$160,"Pressured Selling",'Detalhamento por tela'!$B$2:$B$160,2,'Detalhamento por tela'!$E$2:$E$160,"Tendencioso")>0)+(SUMIFS('Detalhamento por tela'!$J$2:$J$160,'Detalhamento por tela'!$A$2:$A$160,"ChatGPT",'Detalhamento por tela'!$G$2:$G$160,"Persuasive language",'Detalhamento por tela'!$B$2:$B$160,2,'Detalhamento por tela'!$E$2:$E$160,"Tendencioso")>0)+(SUMIFS('Detalhamento por tela'!$J$2:$J$160,'Detalhamento por tela'!$A$2:$A$160,"ChatGPT",'Detalhamento por tela'!$G$2:$G$160,"Bad Defaults/Pre-Selection",'Detalhamento por tela'!$B$2:$B$160,2,'Detalhamento por tela'!$E$2:$E$160,"Tendencioso")>0)+(SUMIFS('Detalhamento por tela'!$J$2:$J$160,'Detalhamento por tela'!$A$2:$A$160,"ChatGPT",'Detalhamento por tela'!$G$2:$G$160,"Positive Or Negative Framing",'Detalhamento por tela'!$B$2:$B$160,2,'Detalhamento por tela'!$E$2:$E$160,"Tendencioso")>0)+(SUMIFS('Detalhamento por tela'!$J$2:$J$160,'Detalhamento por tela'!$A$2:$A$160,"ChatGPT",'Detalhamento por tela'!$G$2:$G$160,"Fear Of Missing Out",'Detalhamento por tela'!$B$2:$B$160,2,'Detalhamento por tela'!$E$2:$E$160,"Tendencioso")>0)+(SUMIFS('Detalhamento por tela'!$J$2:$J$160,'Detalhamento por tela'!$A$2:$A$160,"ChatGPT",'Detalhamento por tela'!$G$2:$G$160,"Feedforward Ambiguity",'Detalhamento por tela'!$B$2:$B$160,2,'Detalhamento por tela'!$E$2:$E$160,"Tendencioso")>0)+(SUMIFS('Detalhamento por tela'!$J$2:$J$160,'Detalhamento por tela'!$A$2:$A$160,"ChatGPT",'Detalhamento por tela'!$G$2:$G$160,"Privacy Zuckering",'Detalhamento por tela'!$B$2:$B$160,2,'Detalhamento por tela'!$E$2:$E$160,"Tendencioso")>0)+(SUMIFS('Detalhamento por tela'!$J$2:$J$160,'Detalhamento por tela'!$A$2:$A$160,"ChatGPT",'Detalhamento por tela'!$G$2:$G$160,"High Demand",'Detalhamento por tela'!$B$2:$B$160,2,'Detalhamento por tela'!$E$2:$E$160,"Tendencioso")>0)+(SUMIFS('Detalhamento por tela'!$J$2:$J$160,'Detalhamento por tela'!$A$2:$A$160,"ChatGPT",'Detalhamento por tela'!$G$2:$G$160,"Low Stock",'Detalhamento por tela'!$B$2:$B$160,2,'Detalhamento por tela'!$E$2:$E$160,"Tendencioso")>0)+(SUMIFS('Detalhamento por tela'!$J$2:$J$160,'Detalhamento por tela'!$A$2:$A$160,"ChatGPT",'Detalhamento por tela'!$G$2:$G$160,"Endorsement And Testimonials",'Detalhamento por tela'!$B$2:$B$160,2,'Detalhamento por tela'!$E$2:$E$160,"Tendencioso")>0)+(SUMIFS('Detalhamento por tela'!$J$2:$J$160,'Detalhamento por tela'!$A$2:$A$160,"ChatGPT",'Detalhamento por tela'!$G$2:$G$160,"Countdown Timer",'Detalhamento por tela'!$B$2:$B$160,2,'Detalhamento por tela'!$E$2:$E$160,"Tendencioso")>0)+(SUMIFS('Detalhamento por tela'!$J$2:$J$160,'Detalhamento por tela'!$A$2:$A$160,"ChatGPT",'Detalhamento por tela'!$G$2:$G$160,"Limited Time Message",'Detalhamento por tela'!$B$2:$B$160,2,'Detalhamento por tela'!$E$2:$E$160,"Tendencioso")>0) -> 9
A12: ChatGPT | B12: 2 | C12: Total | D12: =SUMPRODUCT(1*('Matriz por tela'!$A$6:$A$101="ChatGPT")*('Matriz por tela'!$B$6:$B$101=2)) -> 24 | E12: =SUMPRODUCT(1*('Matriz por tela'!$A$6:$A$101="ChatGPT")*('Matriz por tela'!$B$6:$B$101=2)*('Matriz por tela'!$AB$6:$AB$101>0)) -> 17 | F12: =IFERROR(E12/D12,0) -> 0.70833333 | G12: =SUMIFS('Detalhamento por tela'!$J$2:$J$160,'Detalhamento por tela'!$A$2:$A$160,"ChatGPT",'Detalhamento por tela'!$B$2:$B$160,2) -> 33 | H12: =IFERROR(G12/D12,0) -> 1.375 | I12: =(SUMIFS('Detalhamento por tela'!$J$2:$J$160,'Detalhamento por tela'!$A$2:$A$160,"ChatGPT",'Detalhamento por tela'!$G$2:$G$160,"Dead End",'Detalhamento por tela'!$B$2:$B$160,2)>0)+(SUMIFS('Detalhamento por tela'!$J$2:$J$160,'Detalhamento por tela'!$A$2:$A$160,"ChatGPT",'Detalhamento por tela'!$G$2:$G$160,"Privacy Maze",'Detalhamento por tela'!$B$2:$B$160,2)>0)+(SUMIFS('Detalhamento por tela'!$J$2:$J$160,'Detalhamento por tela'!$A$2:$A$160,"ChatGPT",'Detalhamento por tela'!$G$2:$G$160,"Labyrinthine Navigation",'Detalhamento por tela'!$B$2:$B$160,2)>0)+(SUMIFS('Detalhamento por tela'!$J$2:$J$160,'Detalhamento por tela'!$A$2:$A$160,"ChatGPT",'Detalhamento por tela'!$G$2:$G$160,"Reference Pricing",'Detalhamento por tela'!$B$2:$B$160,2)>0)+(SUMIFS('Detalhamento por tela'!$J$2:$J$160,'Detalhamento por tela'!$A$2:$A$160,"ChatGPT",'Detalhamento por tela'!$G$2:$G$160,"Conflicting Information",'Detalhamento por tela'!$B$2:$B$160,2)>0)+(SUMIFS('Detalhamento por tela'!$J$2:$J$160,'Detalhamento por tela'!$A$2:$A$160,"ChatGPT",'Detalhamento por tela'!$G$2:$G$160,"Information Without Context",'Detalhamento por tela'!$B$2:$B$160,2)>0)+(SUMIFS('Detalhamento por tela'!$J$2:$J$160,'Detalhamento por tela'!$A$2:$A$160,"ChatGPT",'Detalhamento por tela'!$G$2:$G$160,"False Hierarchy",'Detalhamento por tela'!$B$2:$B$160,2)>0)+(SUMIFS('Detalhamento por tela'!$J$2:$J$160,'Detalhamento por tela'!$A$2:$A$160,"ChatGPT",'Detalhamento por tela'!$G$2:$G$160,"Visual Prominence",'Detalhamento por tela'!$B$2:$B$160,2)>0)+(SUMIFS('Detalhamento por tela'!$J$2:$J$160,'Detalhamento por tela'!$A$2:$A$160,"ChatGPT",'Detalhamento por tela'!$G$2:$G$160,"Bundling",'Detalhamento por tela'!$B$2:$B$160,2)>0)+(SUMIFS('Detalhamento por tela'!$J$2:$J$160,'Detalhamento por tela'!$A$2:$A$160,"ChatGPT",'Detalhamento por tela'!$G$2:$G$160,"Pressured Selling",'Detalhamento por tela'!$B$2:$B$160,2)>0)+(SUMIFS('Detalhamento por tela'!$J$2:$J$160,'Detalhamento por tela'!$A$2:$A$160,"ChatGPT",'Detalhamento por tela'!$G$2:$G$160,"Persuasive language",'Detalhamento por tela'!$B$2:$B$160,2)>0)+(SUMIFS('Detalhamento por tela'!$J$2:$J$160,'Detalhamento por tela'!$A$2:$A$160,"ChatGPT",'Detalhamento por tela'!$G$2:$G$160,"Bad Defaults/Pre-Selection",'Detalhamento por tela'!$B$2:$B$160,2)>0)+(SUMIFS('Detalhamento por tela'!$J$2:$J$160,'Detalhamento por tela'!$A$2:$A$160,"ChatGPT",'Detalhamento por tela'!$G$2:$G$160,"Positive Or Negative Framing",'Detalhamento por tela'!$B$2:$B$160,2)>0)+(SUMIFS('Detalhamento por tela'!$J$2:$J$160,'Detalhamento por tela'!$A$2:$A$160,"ChatGPT",'Detalhamento por tela'!$G$2:$G$160,"Fear Of Missing Out",'Detalhamento por tela'!$B$2:$B$160,2)>0)+(SUMIFS('Detalhamento por tela'!$J$2:$J$160,'Detalhamento por tela'!$A$2:$A$160,"ChatGPT",'Detalhamento por tela'!$G$2:$G$160,"Feedforward Ambiguity",'Detalhamento por tela'!$B$2:$B$160,2)>0)+(SUMIFS('Detalhamento por tela'!$J$2:$J$160,'Detalhamento por tela'!$A$2:$A$160,"ChatGPT",'Detalhamento por tela'!$G$2:$G$160,"Privacy Zuckering",'Detalhamento por tela'!$B$2:$B$160,2)>0)+(SUMIFS('Detalhamento por tela'!$J$2:$J$160,'Detalhamento por tela'!$A$2:$A$160,"ChatGPT",'Detalhamento por tela'!$G$2:$G$160,"High Demand",'Detalhamento por tela'!$B$2:$B$160,2)>0)+(SUMIFS('Detalhamento por tela'!$J$2:$J$160,'Detalhamento por tela'!$A$2:$A$160,"ChatGPT",'Detalhamento por tela'!$G$2:$G$160,"Low Stock",'Detalhamento por tela'!$B$2:$B$160,2)>0)+(SUMIFS('Detalhamento por tela'!$J$2:$J$160,'Detalhamento por tela'!$A$2:$A$160,"ChatGPT",'Detalhamento por tela'!$G$2:$G$160,"Endorsement And Testimonials",'Detalhamento por tela'!$B$2:$B$160,2)>0)+(SUMIFS('Detalhamento por tela'!$J$2:$J$160,'Detalhamento por tela'!$A$2:$A$160,"ChatGPT",'Detalhamento por tela'!$G$2:$G$160,"Countdown Timer",'Detalhamento por tela'!$B$2:$B$160,2)>0)+(SUMIFS('Detalhamento por tela'!$J$2:$J$160,'Detalhamento por tela'!$A$2:$A$160,"ChatGPT",'Detalhamento por tela'!$G$2:$G$160,"Limited Time Message",'Detalhamento por tela'!$B$2:$B$160,2)>0) -> 10
A13: ChatGPT | B13: 1 e 2 | C13: Ético | D13: =SUMPRODUCT(1*('Matriz por tela'!$A$6:$A$101="ChatGPT")*('Matriz por tela'!$E$6:$E$101="Ético")) -> 16 | E13: =SUMPRODUCT(1*('Matriz por tela'!$A$6:$A$101="ChatGPT")*('Matriz por tela'!$E$6:$E$101="Ético")*('Matriz por tela'!$AB$6:$AB$101>0)) -> 7 | F13: =IFERROR(E13/D13,0) -> 0.4375 | G13: =SUMIFS('Detalhamento por tela'!$J$2:$J$160,'Detalhamento por tela'!$A$2:$A$160,"ChatGPT",'Detalhamento por tela'!$E$2:$E$160,"Ético") -> 7 | H13: =IFERROR(G13/D13,0) -> 0.4375 | I13: =(SUMIFS('Detalhamento por tela'!$J$2:$J$160,'Detalhamento por tela'!$A$2:$A$160,"ChatGPT",'Detalhamento por tela'!$G$2:$G$160,"Dead End",'Detalhamento por tela'!$E$2:$E$160,"Ético")>0)+(SUMIFS('Detalhamento por tela'!$J$2:$J$160,'Detalhamento por tela'!$A$2:$A$160,"ChatGPT",'Detalhamento por tela'!$G$2:$G$160,"Privacy Maze",'Detalhamento por tela'!$E$2:$E$160,"Ético")>0)+(SUMIFS('Detalhamento por tela'!$J$2:$J$160,'Detalhamento por tela'!$A$2:$A$160,"ChatGPT",'Detalhamento por tela'!$G$2:$G$160,"Labyrinthine Navigation",'Detalhamento por tela'!$E$2:$E$160,"Ético")>0)+(SUMIFS('Detalhamento por tela'!$J$2:$J$160,'Detalhamento por tela'!$A$2:$A$160,"ChatGPT",'Detalhamento por tela'!$G$2:$G$160,"Reference Pricing",'Detalhamento por tela'!$E$2:$E$160,"Ético")>0)+(SUMIFS('Detalhamento por tela'!$J$2:$J$160,'Detalhamento por tela'!$A$2:$A$160,"ChatGPT",'Detalhamento por tela'!$G$2:$G$160,"Conflicting Information",'Detalhamento por tela'!$E$2:$E$160,"Ético")>0)+(SUMIFS('Detalhamento por tela'!$J$2:$J$160,'Detalhamento por tela'!$A$2:$A$160,"ChatGPT",'Detalhamento por tela'!$G$2:$G$160,"Information Without Context",'Detalhamento por tela'!$E$2:$E$160,"Ético")>0)+(SUMIFS('Detalhamento por tela'!$J$2:$J$160,'Detalhamento por tela'!$A$2:$A$160,"ChatGPT",'Detalhamento por tela'!$G$2:$G$160,"False Hierarchy",'Detalhamento por tela'!$E$2:$E$160,"Ético")>0)+(SUMIFS('Detalhamento por tela'!$J$2:$J$160,'Detalhamento por tela'!$A$2:$A$160,"ChatGPT",'Detalhamento por tela'!$G$2:$G$160,"Visual Prominence",'Detalhamento por tela'!$E$2:$E$160,"Ético")>0)+(SUMIFS('Detalhamento por tela'!$J$2:$J$160,'Detalhamento por tela'!$A$2:$A$160,"ChatGPT",'Detalhamento por tela'!$G$2:$G$160,"Bundling",'Detalhamento por tela'!$E$2:$E$160,"Ético")>0)+(SUMIFS('Detalhamento por tela'!$J$2:$J$160,'Detalhamento por tela'!$A$2:$A$160,"ChatGPT",'Detalhamento por tela'!$G$2:$G$160,"Pressured Selling",'Detalhamento por tela'!$E$2:$E$160,"Ético")>0)+(SUMIFS('Detalhamento por tela'!$J$2:$J$160,'Detalhamento por tela'!$A$2:$A$160,"ChatGPT",'Detalhamento por tela'!$G$2:$G$160,"Persuasive language",'Detalhamento por tela'!$E$2:$E$160,"Ético")>0)+(SUMIFS('Detalhamento por tela'!$J$2:$J$160,'Detalhamento por tela'!$A$2:$A$160,"ChatGPT",'Detalhamento por tela'!$G$2:$G$160,"Bad Defaults/Pre-Selection",'Detalhamento por tela'!$E$2:$E$160,"Ético")>0)+(SUMIFS('Detalhamento por tela'!$J$2:$J$160,'Detalhamento por tela'!$A$2:$A$160,"ChatGPT",'Detalhamento por tela'!$G$2:$G$160,"Positive Or Negative Framing",'Detalhamento por tela'!$E$2:$E$160,"Ético")>0)+(SUMIFS('Detalhamento por tela'!$J$2:$J$160,'Detalhamento por tela'!$A$2:$A$160,"ChatGPT",'Detalhamento por tela'!$G$2:$G$160,"Fear Of Missing Out",'Detalhamento por tela'!$E$2:$E$160,"Ético")>0)+(SUMIFS('Detalhamento por tela'!$J$2:$J$160,'Detalhamento por tela'!$A$2:$A$160,"ChatGPT",'Detalhamento por tela'!$G$2:$G$160,"Feedforward Ambiguity",'Detalhamento por tela'!$E$2:$E$160,"Ético")>0)+(SUMIFS('Detalhamento por tela'!$J$2:$J$160,'Detalhamento por tela'!$A$2:$A$160,"ChatGPT",'Detalhamento por tela'!$G$2:$G$160,"Privacy Zuckering",'Detalhamento por tela'!$E$2:$E$160,"Ético")>0)+(SUMIFS('Detalhamento por tela'!$J$2:$J$160,'Detalhamento por tela'!$A$2:$A$160,"ChatGPT",'Detalhamento por tela'!$G$2:$G$160,"High Demand",'Detalhamento por tela'!$E$2:$E$160,"Ético")>0)+(SUMIFS('Detalhamento por tela'!$J$2:$J$160,'Detalhamento por tela'!$A$2:$A$160,"ChatGPT",'Detalhamento por tela'!$G$2:$G$160,"Low Stock",'Detalhamento por tela'!$E$2:$E$160,"Ético")>0)+(SUMIFS('Detalhamento por tela'!$J$2:$J$160,'Detalhamento por tela'!$A$2:$A$160,"ChatGPT",'Detalhamento por tela'!$G$2:$G$160,"Endorsement And Testimonials",'Detalhamento por tela'!$E$2:$E$160,"Ético")>0)+(SUMIFS('Detalhamento por tela'!$J$2:$J$160,'Detalhamento por tela'!$A$2:$A$160,"ChatGPT",'Detalhamento por tela'!$G$2:$G$160,"Countdown Timer",'Detalhamento por tela'!$E$2:$E$160,"Ético")>0)+(SUMIFS('Detalhamento por tela'!$J$2:$J$160,'Detalhamento por tela'!$A$2:$A$160,"ChatGPT",'Detalhamento por tela'!$G$2:$G$160,"Limited Time Message",'Detalhamento por tela'!$E$2:$E$160,"Ético")>0) -> 4
A14: ChatGPT | B14: 1 e 2 | C14: Neutro | D14: =SUMPRODUCT(1*('Matriz por tela'!$A$6:$A$101="ChatGPT")*('Matriz por tela'!$E$6:$E$101="Neutro")) -> 16 | E14: =SUMPRODUCT(1*('Matriz por tela'!$A$6:$A$101="ChatGPT")*('Matriz por tela'!$E$6:$E$101="Neutro")*('Matriz por tela'!$AB$6:$AB$101>0)) -> 12 | F14: =IFERROR(E14/D14,0) -> 0.75 | G14: =SUMIFS('Detalhamento por tela'!$J$2:$J$160,'Detalhamento por tela'!$A$2:$A$160,"ChatGPT",'Detalhamento por tela'!$E$2:$E$160,"Neutro") -> 24 | H14: =IFERROR(G14/D14,0) -> 1.5 | I14: =(SUMIFS('Detalhamento por tela'!$J$2:$J$160,'Detalhamento por tela'!$A$2:$A$160,"ChatGPT",'Detalhamento por tela'!$G$2:$G$160,"Dead End",'Detalhamento por tela'!$E$2:$E$160,"Neutro")>0)+(SUMIFS('Detalhamento por tela'!$J$2:$J$160,'Detalhamento por tela'!$A$2:$A$160,"ChatGPT",'Detalhamento por tela'!$G$2:$G$160,"Privacy Maze",'Detalhamento por tela'!$E$2:$E$160,"Neutro")>0)+(SUMIFS('Detalhamento por tela'!$J$2:$J$160,'Detalhamento por tela'!$A$2:$A$160,"ChatGPT",'Detalhamento por tela'!$G$2:$G$160,"Labyrinthine Navigation",'Detalhamento por tela'!$E$2:$E$160,"Neutro")>0)+(SUMIFS('Detalhamento por tela'!$J$2:$J$160,'Detalhamento por tela'!$A$2:$A$160,"ChatGPT",'Detalhamento por tela'!$G$2:$G$160,"Reference Pricing",'Detalhamento por tela'!$E$2:$E$160,"Neutro")>0)+(SUMIFS('Detalhamento por tela'!$J$2:$J$160,'Detalhamento por tela'!$A$2:$A$160,"ChatGPT",'Detalhamento por tela'!$G$2:$G$160,"Conflicting Information",'Detalhamento por tela'!$E$2:$E$160,"Neutro")>0)+(SUMIFS('Detalhamento por tela'!$J$2:$J$160,'Detalhamento por tela'!$A$2:$A$160,"ChatGPT",'Detalhamento por tela'!$G$2:$G$160,"Information Without Context",'Detalhamento por tela'!$E$2:$E$160,"Neutro")>0)+(SUMIFS('Detalhamento por tela'!$J$2:$J$160,'Detalhamento por tela'!$A$2:$A$160,"ChatGPT",'Detalhamento por tela'!$G$2:$G$160,"False Hierarchy",'Detalhamento por tela'!$E$2:$E$160,"Neutro")>0)+(SUMIFS('Detalhamento por tela'!$J$2:$J$160,'Detalhamento por tela'!$A$2:$A$160,"ChatGPT",'Detalhamento por tela'!$G$2:$G$160,"Visual Prominence",'Detalhamento por tela'!$E$2:$E$160,"Neutro")>0)+(SUMIFS('Detalhamento por tela'!$J$2:$J$160,'Detalhamento por tela'!$A$2:$A$160,"ChatGPT",'Detalhamento por tela'!$G$2:$G$160,"Bundling",'Detalhamento por tela'!$E$2:$E$160,"Neutro")>0)+(SUMIFS('Detalhamento por tela'!$J$2:$J$160,'Detalhamento por tela'!$A$2:$A$160,"ChatGPT",'Detalhamento por tela'!$G$2:$G$160,"Pressured Selling",'Detalhamento por tela'!$E$2:$E$160,"Neutro")>0)+(SUMIFS('Detalhamento por tela'!$J$2:$J$160,'Detalhamento por tela'!$A$2:$A$160,"ChatGPT",'Detalhamento por tela'!$G$2:$G$160,"Persuasive language",'Detalhamento por tela'!$E$2:$E$160,"Neutro")>0)+(SUMIFS('Detalhamento por tela'!$J$2:$J$160,'Detalhamento por tela'!$A$2:$A$160,"ChatGPT",'Detalhamento por tela'!$G$2:$G$160,"Bad Defaults/Pre-Selection",'Detalhamento por tela'!$E$2:$E$160,"Neutro")>0)+(SUMIFS('Detalhamento por tela'!$J$2:$J$160,'Detalhamento por tela'!$A$2:$A$160,"ChatGPT",'Detalhamento por tela'!$G$2:$G$160,"Positive Or Negative Framing",'Detalhamento por tela'!$E$2:$E$160,"Neutro")>0)+(SUMIFS('Detalhamento por tela'!$J$2:$J$160,'Detalhamento por tela'!$A$2:$A$160,"ChatGPT",'Detalhamento por tela'!$G$2:$G$160,"Fear Of Missing Out",'Detalhamento por tela'!$E$2:$E$160,"Neutro")>0)+(SUMIFS('Detalhamento por tela'!$J$2:$J$160,'Detalhamento por tela'!$A$2:$A$160,"ChatGPT",'Detalhamento por tela'!$G$2:$G$160,"Feedforward Ambiguity",'Detalhamento por tela'!$E$2:$E$160,"Neutro")>0)+(SUMIFS('Detalhamento por tela'!$J$2:$J$160,'Detalhamento por tela'!$A$2:$A$160,"ChatGPT",'Detalhamento por tela'!$G$2:$G$160,"Privacy Zuckering",'Detalhamento por tela'!$E$2:$E$160,"Neutro")>0)+(SUMIFS('Detalhamento por tela'!$J$2:$J$160,'Detalhamento por tela'!$A$2:$A$160,"ChatGPT",'Detalhamento por tela'!$G$2:$G$160,"High Demand",'Detalhamento por tela'!$E$2:$E$160,"Neutro")>0)+(SUMIFS('Detalhamento por tela'!$J$2:$J$160,'Detalhamento por tela'!$A$2:$A$160,"ChatGPT",'Detalhamento por tela'!$G$2:$G$160,"Low Stock",'Detalhamento por tela'!$E$2:$E$160,"Neutro")>0)+(SUMIFS('Detalhamento por tela'!$J$2:$J$160,'Detalhamento por tela'!$A$2:$A$160,"ChatGPT",'Detalhamento por tela'!$G$2:$G$160,"Endorsement And Testimonials",'Detalhamento por tela'!$E$2:$E$160,"Neutro")>0)+(SUMIFS('Detalhamento por tela'!$J$2:$J$160,'Detalhamento por tela'!$A$2:$A$160,"ChatGPT",'Detalhamento por tela'!$G$2:$G$160,"Countdown Timer",'Detalhamento por tela'!$E$2:$E$160,"Neutro")>0)+(SUMIFS('Detalhamento por tela'!$J$2:$J$160,'Detalhamento por tela'!$A$2:$A$160,"ChatGPT",'Detalhamento por tela'!$G$2:$G$160,"Limited Time Message",'Detalhamento por tela'!$E$2:$E$160,"Neutro")>0) -> 8
A15: ChatGPT | B15: 1 e 2 | C15: Tendencioso | D15: =SUMPRODUCT(1*('Matriz por tela'!$A$6:$A$101="ChatGPT")*('Matriz por tela'!$E$6:$E$101="Tendencioso")) -> 16 | E15: =SUMPRODUCT(1*('Matriz por tela'!$A$6:$A$101="ChatGPT")*('Matriz por tela'!$E$6:$E$101="Tendencioso")*('Matriz por tela'!$AB$6:$AB$101>0)) -> 13 | F15: =IFERROR(E15/D15,0) -> 0.8125 | G15: =SUMIFS('Detalhamento por tela'!$J$2:$J$160,'Detalhamento por tela'!$A$2:$A$160,"ChatGPT",'Detalhamento por tela'!$E$2:$E$160,"Tendencioso") -> 32 | H15: =IFERROR(G15/D15,0) -> 2 | I15: =(SUMIFS('Detalhamento por tela'!$J$2:$J$160,'Detalhamento por tela'!$A$2:$A$160,"ChatGPT",'Detalhamento por tela'!$G$2:$G$160,"Dead End",'Detalhamento por tela'!$E$2:$E$160,"Tendencioso")>0)+(SUMIFS('Detalhamento por tela'!$J$2:$J$160,'Detalhamento por tela'!$A$2:$A$160,"ChatGPT",'Detalhamento por tela'!$G$2:$G$160,"Privacy Maze",'Detalhamento por tela'!$E$2:$E$160,"Tendencioso")>0)+(SUMIFS('Detalhamento por tela'!$J$2:$J$160,'Detalhamento por tela'!$A$2:$A$160,"ChatGPT",'Detalhamento por tela'!$G$2:$G$160,"Labyrinthine Navigation",'Detalhamento por tela'!$E$2:$E$160,"Tendencioso")>0)+(SUMIFS('Detalhamento por tela'!$J$2:$J$160,'Detalhamento por tela'!$A$2:$A$160,"ChatGPT",'Detalhamento por tela'!$G$2:$G$160,"Reference Pricing",'Detalhamento por tela'!$E$2:$E$160,"Tendencioso")>0)+(SUMIFS('Detalhamento por tela'!$J$2:$J$160,'Detalhamento por tela'!$A$2:$A$160,"ChatGPT",'Detalhamento por tela'!$G$2:$G$160,"Conflicting Information",'Detalhamento por tela'!$E$2:$E$160,"Tendencioso")>0)+(SUMIFS('Detalhamento por tela'!$J$2:$J$160,'Detalhamento por tela'!$A$2:$A$160,"ChatGPT",'Detalhamento por tela'!$G$2:$G$160,"Information Without Context",'Detalhamento por tela'!$E$2:$E$160,"Tendencioso")>0)+(SUMIFS('Detalhamento por tela'!$J$2:$J$160,'Detalhamento por tela'!$A$2:$A$160,"ChatGPT",'Detalhamento por tela'!$G$2:$G$160,"False Hierarchy",'Detalhamento por tela'!$E$2:$E$160,"Tendencioso")>0)+(SUMIFS('Detalhamento por tela'!$J$2:$J$160,'Detalhamento por tela'!$A$2:$A$160,"ChatGPT",'Detalhamento por tela'!$G$2:$G$160,"Visual Prominence",'Detalhamento por tela'!$E$2:$E$160,"Tendencioso")>0)+(SUMIFS('Detalhamento por tela'!$J$2:$J$160,'Detalhamento por tela'!$A$2:$A$160,"ChatGPT",'Detalhamento por tela'!$G$2:$G$160,"Bundling",'Detalhamento por tela'!$E$2:$E$160,"Tendencioso")>0)+(SUMIFS('Detalhamento por tela'!$J$2:$J$160,'Detalhamento por tela'!$A$2:$A$160,"ChatGPT",'Detalhamento por tela'!$G$2:$G$160,"Pressured Selling",'Detalhamento por tela'!$E$2:$E$160,"Tendencioso")>0)+(SUMIFS('Detalhamento por tela'!$J$2:$J$160,'Detalhamento por tela'!$A$2:$A$160,"ChatGPT",'Detalhamento por tela'!$G$2:$G$160,"Persuasive language",'Detalhamento por tela'!$E$2:$E$160,"Tendencioso")>0)+(SUMIFS('Detalhamento por tela'!$J$2:$J$160,'Detalhamento por tela'!$A$2:$A$160,"ChatGPT",'Detalhamento por tela'!$G$2:$G$160,"Bad Defaults/Pre-Selection",'Detalhamento por tela'!$E$2:$E$160,"Tendencioso")>0)+(SUMIFS('Detalhamento por tela'!$J$2:$J$160,'Detalhamento por tela'!$A$2:$A$160,"ChatGPT",'Detalhamento por tela'!$G$2:$G$160,"Positive Or Negative Framing",'Detalhamento por tela'!$E$2:$E$160,"Tendencioso")>0)+(SUMIFS('Detalhamento por tela'!$J$2:$J$160,'Detalhamento por tela'!$A$2:$A$160,"ChatGPT",'Detalhamento por tela'!$G$2:$G$160,"Fear Of Missing Out",'Detalhamento por tela'!$E$2:$E$160,"Tendencioso")>0)+(SUMIFS('Detalhamento por tela'!$J$2:$J$160,'Detalhamento por tela'!$A$2:$A$160,"ChatGPT",'Detalhamento por tela'!$G$2:$G$160,"Feedforward Ambiguity",'Detalhamento por tela'!$E$2:$E$160,"Tendencioso")>0)+(SUMIFS('Detalhamento por tela'!$J$2:$J$160,'Detalhamento por tela'!$A$2:$A$160,"ChatGPT",'Detalhamento por tela'!$G$2:$G$160,"Privacy Zuckering",'Detalhamento por tela'!$E$2:$E$160,"Tendencioso")>0)+(SUMIFS('Detalhamento por tela'!$J$2:$J$160,'Detalhamento por tela'!$A$2:$A$160,"ChatGPT",'Detalhamento por tela'!$G$2:$G$160,"High Demand",'Detalhamento por tela'!$E$2:$E$160,"Tendencioso")>0)+(SUMIFS('Detalhamento por tela'!$J$2:$J$160,'Detalhamento por tela'!$A$2:$A$160,"ChatGPT",'Detalhamento por tela'!$G$2:$G$160,"Low Stock",'Detalhamento por tela'!$E$2:$E$160,"Tendencioso")>0)+(SUMIFS('Detalhamento por tela'!$J$2:$J$160,'Detalhamento por tela'!$A$2:$A$160,"ChatGPT",'Detalhamento por tela'!$G$2:$G$160,"Endorsement And Testimonials",'Detalhamento por tela'!$E$2:$E$160,"Tendencioso")>0)+(SUMIFS('Detalhamento por tela'!$J$2:$J$160,'Detalhamento por tela'!$A$2:$A$160,"ChatGPT",'Detalhamento por tela'!$G$2:$G$160,"Countdown Timer",'Detalhamento por tela'!$E$2:$E$160,"Tendencioso")>0)+(SUMIFS('Detalhamento por tela'!$J$2:$J$160,'Detalhamento por tela'!$A$2:$A$160,"ChatGPT",'Detalhamento por tela'!$G$2:$G$160,"Limited Time Message",'Detalhamento por tela'!$E$2:$E$160,"Tendencioso")>0) -> 12
